Workbook
Name MG_Alprazolam: 'Med Reference'!$G$57:$J$57
Name MG_Aripiprazole: 'Med Reference'!$G$54:$L$54
Name MG_Bupropion: 'Med Reference'!$G$44:$K$44
Name MG_Buspirone: 'Med Reference'!$G$60:$J$60
Name MG_Carbamazepine: 'Med Reference'!$G$56:$I$56
Name MG_Citalopram: 'Med Reference'!$G$43:$I$43
Name MG_Clonazepam: 'Med Reference'!$G$59:$I$59
Name MG_Diazepam: 'Med Reference'!$G$62:$I$62
Name MG_Divalproex_Valproate: 'Med Reference'!$G$50:$I$50
Name MG_Duloxetine: 'Med Reference'!$G$46:$I$46
Name MG_Escitalopram: 'Med Reference'!$G$42:$I$42
Name MG_Fluoxetine: 'Med Reference'!$G$41:$J$41
Name MG_Hydroxyzine: 'Med Reference'!$G$61:$J$61
Name MG_Lamotrigine: 'Med Reference'!$G$51:$K$51
Name MG_Lithium: 'Med Reference'!$G$49:$J$49
Name MG_Lorazepam: 'Med Reference'!$G$58:$I$58
Name MG_Mirtazapine: 'Med Reference'!$G$47:$J$47
Name MG_Olanzapine: 'Med Reference'!$G$53:$L$53
Name MG_Quetiapine: 'Med Reference'!$G$52:$L$52
Name MG_Risperidone: 'Med Reference'!$G$55:$L$55
Name MG_Sertraline: 'Med Reference'!$G$40:$I$40
Name MG_Trazodone: 'Med Reference'!$G$48:$J$48
Name MG_Venlafaxine: 'Med Reference'!$G$45:$J$45

Sheet Dashboard
B2: Discharge Outcomes | N2: As of | O2: =TODAY() -> 46242
B3: Live from Discharge + Yearly Log · updates automatically each time this file is opened
B6: TOTAL DISCHARGES | D6: MET DISCHARGE PLAN | F6: THIS MONTH | H6: THIS WEEK | J6: DOCS OBTAINED
B8: =SUMPRODUCT((YEAR(Discharge!$T$5:$T$204)=YEAR($O$2))*(Discharge!$T$5:$T$204<>""))+SUMPRODUCT((YEAR('Yearly Log'!$T$5:$T$204)=YEAR($O$2))*('Yearly Log'!$T$5:$T$204<>"")) -> 61 | D8: =IFERROR((SUMPRODUCT((YEAR(Discharge!$T$5:$T$204)=YEAR($O$2))*(Discharge!$U$5:$U$204="✓"))+SUMPRODUCT((YEAR('Yearly Log'!$T$5:$T$204)=YEAR($O$2))*('Yearly Log'!$U$5:$U$204="✓")))/(SUMPRODUCT((YEAR(Discharge!$T$5:$T$204)=YEAR($O$2))*(Discharge!$T$5:$T$204<>""))+SUMPRODUCT((YEAR('Yearly Log'!$T$5:$T$204)=YEAR($O$2))*('Yearly Log'!$T$5:$T$204<>""))),0) -> 0.3442623 | F8: =SUMPRODUCT(((MONTH(Discharge!$T$5:$T$204)=MONTH($O$2))*(YEAR(Discharge!$T$5:$T$204)=YEAR($O$2)))*(Discharge!$T$5:$T$204<>""))+SUMPRODUCT(((MONTH('Yearly Log'!$T$5:$T$204)=MONTH($O$2))*(YEAR('Yearly Log'!$T$5:$T$204)=YEAR($O$2)))*('Yearly Log'!$T$5:$T$204<>"")) -> 0 | H8: =SUMPRODUCT(((Discharge!$T$5:$T$204>=$O$2-WEEKDAY($O$2,2)+1)*(Discharge!$T$5:$T$204<=$O$2-WEEKDAY($O$2,2)+7))*(Discharge!$T$5:$T$204<>""))+SUMPRODUCT((('Yearly Log'!$T$5:$T$204>=$O$2-WEEKDAY($O$2,2)+1)*('Yearly Log'!$T$5:$T$204<=$O$2-WEEKDAY($O$2,2)+7))*('Yearly Log'!$T$5:$T$204<>"")) -> 0 | J8: =AVERAGE(IFERROR((SUMPRODUCT((YEAR(Discharge!$T$5:$T$204)=YEAR($O$2))*(Discharge!$V$5:$V$204="✓"))+SUMPRODUCT((YEAR('Yearly Log'!$T$5:$T$204)=YEAR($O$2))*('Yearly Log'!$V$5:$V$204="✓")))/(SUMPRODUCT((YEAR(Discharge!$T$5:$T$204)=YEAR($O$2))*(Discharge!$T$5:$T$204<>""))+SUMPRODUCT((YEAR('Yearly Log'!$T$5:$T$204)=YEAR($O$2))*('Yearly Log'!$T$5:$T$204<>""))),0),IFERROR((SUMPRODUCT((YEAR(Discharge!$T$5:$T$204)=YEAR($O$2))*(Discharge!$W$5:$W$204="✓"))+SUMPRODUCT((YEAR('Yearly Log'!$T$5:$T$204)=YEAR($O$2))*('Yearly Log'!$W$5:$W$204="✓")))/(SUMPRODUCT((YEAR(Discharge!$T$5:$T$204)=YEAR($O$2))*(Discharge!$T$5:$T$204<>""))+SUMPRODUCT((YEAR('Yearly Log'!$T$5:$T$204)=YEAR($O$2))*('Yearly Log'!$T$5:$T$204<>""))),0),IFERROR((SUMPRODUCT((YEAR(Discharge!$T$5:$T$204)=YEAR($O$2))*(Discharge!$X$5:$X$204="✓"))+SUMPRODUCT((YEAR('Yearly Log'!$T$5:$T$204)=YEAR($O$2))*('Yearly Log'!$X$5:$X$204="✓")))/(SUMPRODUCT((YEAR(Discharge!$T$5:$T$204)=YEAR($O$2))*(Discharge!$T$5:$T$204<>""))+SUMPRODUCT((YEAR('Yearly Log'!$T$5:$T$204)=YEAR($O$2))*('Yearly Log'!$T$5:$T$204<>""))),0),IFERROR((SUMPRODUCT((YEAR(Discharge!$T$5:$T$204)=YEAR($O$2))*(Discharge!$Y$5:$Y$204="✓"))+SUMPRODUCT((YEAR('Yearly Log'!$T$5:$T$204)=YEAR($O$2))*('Yearly Log'!$Y$5:$Y$204="✓")))/(SUMPRODUCT((YEAR(Discharge!$T$5:$T$204)=YEAR($O$2))*(Discharge!$T$5:$T$204<>""))+SUMPRODUCT((YEAR('Yearly Log'!$T$5:$T$204)=YEAR($O$2))*('Yearly Log'!$T$5:$T$204<>""))),0)) -> 0.31557377
B9: YEAR TO DATE | D9: YEAR TO DATE | F9: DISCHARGES | H9: DISCHARGES | J9: AVG. YTD
B12: Referral Source | F12: Documents Obtained · % of discharges (YTD) | J12: Placements · Treatment / Sober Living / Shelter (YTD)
B13: Oceans | C13: =SUMPRODUCT((YEAR(Discharge!$T$5:$T$204)=YEAR($O$2))*(Discharge!$G$5:$G$204="Oceans"))+SUMPRODUCT((YEAR('Yearly Log'!$T$5:$T$204)=YEAR($O$2))*('Yearly Log'!$G$5:$G$204="Oceans")) -> 13 | F13: ID | G13: =IFERROR((SUMPRODUCT((YEAR(Discharge!$T$5:$T$204)=YEAR($O$2))*(Discharge!$V$5:$V$204="✓"))+SUMPRODUCT((YEAR('Yearly Log'!$T$5:$T$204)=YEAR($O$2))*('Yearly Log'!$V$5:$V$204="✓")))/(SUMPRODUCT((YEAR(Discharge!$T$5:$T$204)=YEAR($O$2))*(Discharge!$T$5:$T$204<>""))+SUMPRODUCT((YEAR('Yearly Log'!$T$5:$T$204)=YEAR($O$2))*('Yearly Log'!$T$5:$T$204<>""))),0) -> 0.36065574 | J13: Cenikor | L13: =SUMPRODUCT((YEAR(Discharge!$T$5:$T$204)=YEAR($O$2))*(Discharge!$P$5:$P$204="Cenikor"))+SUMPRODUCT((YEAR('Yearly Log'!$T$5:$T$204)=YEAR($O$2))*('Yearly Log'!$P$5:$P$204="Cenikor")) -> 8
B14: Bayview | C14: =SUMPRODUCT((YEAR(Discharge!$T$5:$T$204)=YEAR($O$2))*(Discharge!$G$5:$G$204="Bayview"))+SUMPRODUCT((YEAR('Yearly Log'!$T$5:$T$204)=YEAR($O$2))*('Yearly Log'!$G$5:$G$204="Bayview")) -> 6 | F14: Bus Pass | G14: =IFERROR((SUMPRODUCT((YEAR(Discharge!$T$5:$T$204)=YEAR($O$2))*(Discharge!$W$5:$W$204="✓"))+SUMPRODUCT((YEAR('Yearly Log'!$T$5:$T$204)=YEAR($O$2))*('Yearly Log'!$W$5:$W$204="✓")))/(SUMPRODUCT((YEAR(Discharge!$T$5:$T$204)=YEAR($O$2))*(Discharge!$T$5:$T$204<>""))+SUMPRODUCT((YEAR('Yearly Log'!$T$5:$T$204)=YEAR($O$2))*('Yearly Log'!$T$5:$T$204<>""))),0) -> 0.27868852 | J14: Lifetime Recovery | L14: =SUMPRODUCT((YEAR(Discharge!$T$5:$T$204)=YEAR($O$2))*(Discharge!$P$5:$P$204="Lifetime Recovery"))+SUMPRODUCT((YEAR('Yearly Log'!$T$5:$T$204)=YEAR($O$2))*('Yearly Log'!$P$5:$P$204="Lifetime Recovery")) -> 3
B15: PubDef | C15: =SUMPRODUCT((YEAR(Discharge!$T$5:$T$204)=YEAR($O$2))*(Discharge!$G$5:$G$204="PubDef"))+SUMPRODUCT((YEAR('Yearly Log'!$T$5:$T$204)=YEAR($O$2))*('Yearly Log'!$G$5:$G$204="PubDef")) -> 5 | F15: Clinic Card | G15: =IFERROR((SUMPRODUCT((YEAR(Discharge!$T$5:$T$204)=YEAR($O$2))*(Discharge!$X$5:$X$204="✓"))+SUMPRODUCT((YEAR('Yearly Log'!$T$5:$T$204)=YEAR($O$2))*('Yearly Log'!$X$5:$X$204="✓")))/(SUMPRODUCT((YEAR(Discharge!$T$5:$T$204)=YEAR($O$2))*(Discharge!$T$5:$T$204<>""))+SUMPRODUCT((YEAR('Yearly Log'!$T$5:$T$204)=YEAR($O$2))*('Yearly Log'!$T$5:$T$204<>""))),0) -> 0.31147541 | J15: Liberty Lodge | L15: =SUMPRODUCT((YEAR(Discharge!$T$5:$T$204)=YEAR($O$2))*(Discharge!$P$5:$P$204="Liberty Lodge"))+SUMPRODUCT((YEAR('Yearly Log'!$T$5:$T$204)=YEAR($O$2))*('Yearly Log'!$P$5:$P$204="Liberty Lodge")) -> 8
B16: MCOT | C16: =SUMPRODUCT((YEAR(Discharge!$T$5:$T$204)=YEAR($O$2))*(Discharge!$G$5:$G$204="MCOT"))+SUMPRODUCT((YEAR('Yearly Log'!$T$5:$T$204)=YEAR($O$2))*('Yearly Log'!$G$5:$G$204="MCOT")) -> 9 | F16: SNAP | G16: =IFERROR((SUMPRODUCT((YEAR(Discharge!$T$5:$T$204)=YEAR($O$2))*(Discharge!$Y$5:$Y$204="✓"))+SUMPRODUCT((YEAR('Yearly Log'!$T$5:$T$204)=YEAR($O$2))*('Yearly Log'!$Y$5:$Y$204="✓")))/(SUMPRODUCT((YEAR(Discharge!$T$5:$T$204)=YEAR($O$2))*(Discharge!$T$5:$T$204<>""))+SUMPRODUCT((YEAR('Yearly Log'!$T$5:$T$204)=YEAR($O$2))*('Yearly Log'!$T$5:$T$204<>""))),0) -> 0.31147541 | J16: Oxford House | L16: =SUMPRODUCT((YEAR(Discharge!$T$5:$T$204)=YEAR($O$2))*(Discharge!$Q$5:$Q$204="Oxford House"))+SUMPRODUCT((YEAR('Yearly Log'!$T$5:$T$204)=YEAR($O$2))*('Yearly Log'!$Q$5:$Q$204="Oxford House")) -> 5
B17: CaseMgr | C17: =SUMPRODUCT((YEAR(Discharge!$T$5:$T$204)=YEAR($O$2))*(Discharge!$G$5:$G$204="CaseMgr"))+SUMPRODUCT((YEAR('Yearly Log'!$T$5:$T$204)=YEAR($O$2))*('Yearly Log'!$G$5:$G$204="CaseMgr")) -> 4 | J17: Wenholtz House | L17: =SUMPRODUCT((YEAR(Discharge!$T$5:$T$204)=YEAR($O$2))*(Discharge!$Q$5:$Q$204="Wenholtz House"))+SUMPRODUCT((YEAR('Yearly Log'!$T$5:$T$204)=YEAR($O$2))*('Yearly Log'!$Q$5:$Q$204="Wenholtz House")) -> 2
B18: OCR | C18: =SUMPRODUCT((YEAR(Discharge!$T$5:$T$204)=YEAR($O$2))*(Discharge!$G$5:$G$204="OCR"))+SUMPRODUCT((YEAR('Yearly Log'!$T$5:$T$204)=YEAR($O$2))*('Yearly Log'!$G$5:$G$204="OCR")) -> 7 | F18: Met Discharge Plan · YTD | J18: Rustic House | L18: =SUMPRODUCT((YEAR(Discharge!$T$5:$T$204)=YEAR($O$2))*(Discharge!$Q$5:$Q$204="Rustic House"))+SUMPRODUCT((YEAR('Yearly Log'!$T$5:$T$204)=YEAR($O$2))*('Yearly Log'!$Q$5:$Q$204="Rustic House")) -> 2
B19: IDD | C19: =SUMPRODUCT((YEAR(Discharge!$T$5:$T$204)=YEAR($O$2))*(Discharge!$G$5:$G$204="IDD"))+SUMPRODUCT((YEAR('Yearly Log'!$T$5:$T$204)=YEAR($O$2))*('Yearly Log'!$G$5:$G$204="IDD")) -> 2 | F19: Met | G19: =SUMPRODUCT((YEAR(Discharge!$T$5:$T$204)=YEAR($O$2))*(Discharge!$U$5:$U$204="✓"))+SUMPRODUCT((YEAR('Yearly Log'!$T$5:$T$204)=YEAR($O$2))*('Yearly Log'!$U$5:$U$204="✓")) -> 21 | J19: Broken Chains | L19: =SUMPRODUCT((YEAR(Discharge!$T$5:$T$204)=YEAR($O$2))*(Discharge!$Q$5:$Q$204="Broken Chains"))+SUMPRODUCT((YEAR('Yearly Log'!$T$5:$T$204)=YEAR($O$2))*('Yearly Log'!$Q$5:$Q$204="Broken Chains")) -> 1
B20: OTHER | C20: =SUMPRODUCT((YEAR(Discharge!$T$5:$T$204)=YEAR($O$2))*(Discharge!$G$5:$G$204="OTHER"))+SUMPRODUCT((YEAR('Yearly Log'!$T$5:$T$204)=YEAR($O$2))*('Yearly Log'!$G$5:$G$204="OTHER")) -> 6 | F20: Not Met | G20: =SUMPRODUCT((YEAR(Discharge!$T$5:$T$204)=YEAR($O$2))*(Discharge!$U$5:$U$204="✗"))+SUMPRODUCT((YEAR('Yearly Log'!$T$5:$T$204)=YEAR($O$2))*('Yearly Log'!$U$5:$U$204="✗")) -> 9 | J20: Good Sam | L20: =SUMPRODUCT((YEAR(Discharge!$T$5:$T$204)=YEAR($O$2))*(Discharge!$O$5:$O$204="Good Sam"))+SUMPRODUCT((YEAR('Yearly Log'!$T$5:$T$204)=YEAR($O$2))*('Yearly Log'!$O$5:$O$204="Good Sam")) -> 15
J21: Salvation Army | L21: =SUMPRODUCT((YEAR(Discharge!$T$5:$T$204)=YEAR($O$2))*(Discharge!$O$5:$O$204="Salvation Army"))+SUMPRODUCT((YEAR('Yearly Log'!$T$5:$T$204)=YEAR($O$2))*('Yearly Log'!$O$5:$O$204="Salvation Army")) -> 13
B23: AVG. LENGTH OF STAY | D23: VS. LAST MONTH
B25: =IFERROR((SUMPRODUCT((YEAR(Discharge!$T$5:$T$204)=YEAR($O$2))*(Discharge!$T$5:$T$204<>"")*(Discharge!$C$5:$C$204<>"")*(Discharge!$T$5:$T$204-Discharge!$C$5:$C$204))+SUMPRODUCT((YEAR('Yearly Log'!$T$5:$T$204)=YEAR($O$2))*('Yearly Log'!$T$5:$T$204<>"")*('Yearly Log'!$C$5:$C$204<>"")*('Yearly Log'!$T$5:$T$204-'Yearly Log'!$C$5:$C$204)))/(SUMPRODUCT((YEAR(Discharge!$T$5:$T$204)=YEAR($O$2))*(Discharge!$T$5:$T$204<>"")*(Discharge!$C$5:$C$204<>""))+SUMPRODUCT((YEAR('Yearly Log'!$T$5:$T$204)=YEAR($O$2))*('Yearly Log'!$T$5:$T$204<>"")*('Yearly Log'!$C$5:$C$204<>""))),0) -> 25.307692 | D25: =IFERROR((SUMPRODUCT(((MONTH(Discharge!$T$5:$T$204)=MONTH($O$2))*(YEAR(Discharge!$T$5:$T$204)=YEAR($O$2)))*(Discharge!$T$5:$T$204<>""))+SUMPRODUCT(((MONTH('Yearly Log'!$T$5:$T$204)=MONTH($O$2))*(YEAR('Yearly Log'!$T$5:$T$204)=YEAR($O$2)))*('Yearly Log'!$T$5:$T$204<>"")))-(SUMPRODUCT(((MONTH(Discharge!$T$5:$T$204)=MONTH(EDATE($O$2,-1)))*(YEAR(Discharge!$T$5:$T$204)=YEAR(EDATE($O$2,-1))))*(Discharge!$T$5:$T$204<>""))+SUMPRODUCT(((MONTH('Yearly Log'!$T$5:$T$204)=MONTH(EDATE($O$2,-1)))*(YEAR('Yearly Log'!$T$5:$T$204)=YEAR(EDATE($O$2,-1))))*('Yearly Log'!$T$5:$T$204<>""))),0) -> -41
B26: DAYS, YTD | D26: CHANGE IN DISCHARGES
B32: Discharges by Month
B33: Month | C33: Discharges
B34: Jan | C34: =SUMPRODUCT(((MONTH(Discharge!$T$5:$T$204)=1)*(YEAR(Discharge!$T$5:$T$204)=YEAR($O$2)))*(Discharge!$T$5:$T$204<>""))+SUMPRODUCT(((MONTH('Yearly Log'!$T$5:$T$204)=1)*(YEAR('Yearly Log'!$T$5:$T$204)=YEAR($O$2)))*('Yearly Log'!$T$5:$T$204<>"")) -> 6
B35: Feb | C35: =SUMPRODUCT(((MONTH(Discharge!$T$5:$T$204)=2)*(YEAR(Discharge!$T$5:$T$204)=YEAR($O$2)))*(Discharge!$T$5:$T$204<>""))+SUMPRODUCT(((MONTH('Yearly Log'!$T$5:$T$204)=2)*(YEAR('Yearly Log'!$T$5:$T$204)=YEAR($O$2)))*('Yearly Log'!$T$5:$T$204<>"")) -> 4
B36: Mar | C36: =SUMPRODUCT(((MONTH(Discharge!$T$5:$T$204)=3)*(YEAR(Discharge!$T$5:$T$204)=YEAR($O$2)))*(Discharge!$T$5:$T$204<>""))+SUMPRODUCT(((MONTH('Yearly Log'!$T$5:$T$204)=3)*(YEAR('Yearly Log'!$T$5:$T$204)=YEAR($O$2)))*('Yearly Log'!$T$5:$T$204<>"")) -> 2
B37: Apr | C37: =SUMPRODUCT(((MONTH(Discharge!$T$5:$T$204)=4)*(YEAR(Discharge!$T$5:$T$204)=YEAR($O$2)))*(Discharge!$T$5:$T$204<>""))+SUMPRODUCT(((MONTH('Yearly Log'!$T$5:$T$204)=4)*(YEAR('Yearly Log'!$T$5:$T$204)=YEAR($O$2)))*('Yearly Log'!$T$5:$T$204<>"")) -> 3
B38: May | C38: =SUMPRODUCT(((MONTH(Discharge!$T$5:$T$204)=5)*(YEAR(Discharge!$T$5:$T$204)=YEAR($O$2)))*(Discharge!$T$5:$T$204<>""))+SUMPRODUCT(((MONTH('Yearly Log'!$T$5:$T$204)=5)*(YEAR('Yearly Log'!$T$5:$T$204)=YEAR($O$2)))*('Yearly Log'!$T$5:$T$204<>"")) -> 3
B39: Jun | C39: =SUMPRODUCT(((MONTH(Discharge!$T$5:$T$204)=6)*(YEAR(Discharge!$T$5:$T$204)=YEAR($O$2)))*(Discharge!$T$5:$T$204<>""))+SUMPRODUCT(((MONTH('Yearly Log'!$T$5:$T$204)=6)*(YEAR('Yearly Log'!$T$5:$T$204)=YEAR($O$2)))*('Yearly Log'!$T$5:$T$204<>"")) -> 2
B40: Jul | C40: =SUMPRODUCT(((MONTH(Discharge!$T$5:$T$204)=7)*(YEAR(Discharge!$T$5:$T$204)=YEAR($O$2)))*(Discharge!$T$5:$T$204<>""))+SUMPRODUCT(((MONTH('Yearly Log'!$T$5:$T$204)=7)*(YEAR('Yearly Log'!$T$5:$T$204)=YEAR($O$2)))*('Yearly Log'!$T$5:$T$204<>"")) -> 41
B41: Aug | C41: =SUMPRODUCT(((MONTH(Discharge!$T$5:$T$204)=8)*(YEAR(Discharge!$T$5:$T$204)=YEAR($O$2)))*(Discharge!$T$5:$T$204<>""))+SUMPRODUCT(((MONTH('Yearly Log'!$T$5:$T$204)=8)*(YEAR('Yearly Log'!$T$5:$T$204)=YEAR($O$2)))*('Yearly Log'!$T$5:$T$204<>"")) -> 0
B42: Sep | C42: =SUMPRODUCT(((MONTH(Discharge!$T$5:$T$204)=9)*(YEAR(Discharge!$T$5:$T$204)=YEAR($O$2)))*(Discharge!$T$5:$T$204<>""))+SUMPRODUCT(((MONTH('Yearly Log'!$T$5:$T$204)=9)*(YEAR('Yearly Log'!$T$5:$T$204)=YEAR($O$2)))*('Yearly Log'!$T$5:$T$204<>"")) -> 0
B43: Oct | C43: =SUMPRODUCT(((MONTH(Discharge!$T$5:$T$204)=10)*(YEAR(Discharge!$T$5:$T$204)=YEAR($O$2)))*(Discharge!$T$5:$T$204<>""))+SUMPRODUCT(((MONTH('Yearly Log'!$T$5:$T$204)=10)*(YEAR('Yearly Log'!$T$5:$T$204)=YEAR($O$2)))*('Yearly Log'!$T$5:$T$204<>"")) -> 0
B44: Nov | C44: =SUMPRODUCT(((MONTH(Discharge!$T$5:$T$204)=11)*(YEAR(Discharge!$T$5:$T$204)=YEAR($O$2)))*(Discharge!$T$5:$T$204<>""))+SUMPRODUCT(((MONTH('Yearly Log'!$T$5:$T$204)=11)*(YEAR('Yearly Log'!$T$5:$T$204)=YEAR($O$2)))*('Yearly Log'!$T$5:$T$204<>"")) -> 0
B45: Dec | C45: =SUMPRODUCT(((MONTH(Discharge!$T$5:$T$204)=12)*(YEAR(Discharge!$T$5:$T$204)=YEAR($O$2)))*(Discharge!$T$5:$T$204<>""))+SUMPRODUCT(((MONTH('Yearly Log'!$T$5:$T$204)=12)*(YEAR('Yearly Log'!$T$5:$T$204)=YEAR($O$2)))*('Yearly Log'!$T$5:$T$204<>"")) -> 0

Sheet Client Needs Tracker
A1: Client Needs Tracker
A2: Select ✓ if the client has it / it's met, ✗ if still needed. Resource highlights follow ID, Substance use, and Employed status. See Medications tab, linked by Member ID.
A4: Member ID | B4: Client name | C4: Admit date | D4: Days admitted | E4: LOC | F4: Case Manager | G4: Referral source | H4: Employed (Y/N) | I4: Substance use | J4: ID | K4: SNAP | L4: Clinic Card | M4: Free Phone | N4: Bus Pass | O4: Shelter | P4: Treatment Center | Q4: Sober Living | R4: Notes | S4: Bed | T4: Discharged | U4: Discharge Date
A5: 102558 | B5: Joe Jackson | C5: 46228 | D5: =IF(C5="","",TODAY()-C5) -> 14 | E5: TBD | F5: TBD | G5: PubDef | H5: Y | I5: ✓ | J5: ✗ | S5: M - 1A
A6: 3520025 | B6: Yusef Jui | C6: 46240 | D6: =IF(C6="","",TODAY()-C6) -> 2 | E6: LOC2 | G6: Bayview | H6: Y | I6: ✓ | J6: ✓ | S6: M - 1B
D7: =IF(C7="","",TODAY()-C7) | S7: M - 2A
D8: =IF(C8="","",TODAY()-C8) | S8: M - 2B
D9: =IF(C9="","",TODAY()-C9) | S9: M - 3A
D10: =IF(C10="","",TODAY()-C10) | S10: M - 3B
D11: =IF(C11="","",TODAY()-C11) | S11: M - 4A
D12: =IF(C12="","",TODAY()-C12) | S12: M - 4B
A13: 102558 | B13: Brenda Homes | C13: 46223 | D13: =IF(C13="","",TODAY()-C13) -> 19 | E13: LOC3 | F13: TBD | G13: Bayview | H13: Y | I13: ✓ | J13: ✓ | S13: F - 1A
A14: 10223 | B14: Lisa Lou | C14: 46231 | D14: =IF(C14="","",TODAY()-C14) -> 11 | S14: F - 1B
A15: 10101010 | B15: Betty Boop | C15: 46237 | D15: =IF(C15="","",TODAY()-C15) -> 5 | S15: F - 2A
A16: 25585 | B16: lololo kkk | C16: 46239 | D16: =IF(C16="","",TODAY()-C16) -> 3 | S16: F - 2B
A17: 588588 | B17: Jessica Simpson | C17: 46238 | D17: =IF(C17="","",TODAY()-C17) -> 4 | S17: F - 3A
A18: 3855 | B18: Manuel Lewis | C18: 46205 | D18: =IF(C18="","",TODAY()-C18) -> 37 | E18: LOC5 | F18: J. Wilkers | G18: PubDef | H18: Y | I18: ✗ | J18: ✓ | S18: F - 3B
D19: =IF(C19="","",TODAY()-C19) | S19: F - 4A
D20: =IF(C20="","",TODAY()-C20) | S20: F - 4B
A23: Needs summary (counts as of last save)
A24: Need | B24: Have it (✓) | C24: Still need (✗)
A25: Substance use | B25: =COUNTIF(I5:I20,"✓") -> 3 | C25: =COUNTIF(I5:I20,"✗") -> 1
A26: ID | B26: =COUNTIF(J5:J20,"✓") -> 3 | C26: =COUNTIF(J5:J20,"✗") -> 1
A27: SNAP | B27: =COUNTIF(K5:K20,"✓") -> 0 | C27: =COUNTIF(K5:K20,"✗") -> 0
A28: Clinic Card | B28: =COUNTIF(L5:L20,"✓") -> 0 | C28: =COUNTIF(L5:L20,"✗") -> 0
A29: Free Phone | B29: =COUNTIF(M5:M20,"✓") -> 0 | C29: =COUNTIF(M5:M20,"✗") -> 0
A30: Bus Pass | B30: =COUNTIF(N5:N20,"✓") -> 0 | C30: =COUNTIF(N5:N20,"✗") -> 0
A32: Treatment Center placements
A33: Cenikor | B33: =COUNTIF(P5:P20,"Cenikor") -> 0
A34: Lifetime Recovery | B34: =COUNTIF(P5:P20,"Lifetime Recovery") -> 0
A35: Liberty Lodge | B35: =COUNTIF(P5:P20,"Liberty Lodge") -> 0
A37: Sober Living placements
A38: Oxford House | B38: =COUNTIF(Q5:Q20,"Oxford House") -> 0
A39: Wenholtz House | B39: =COUNTIF(Q5:Q20,"Wenholtz House") -> 0
A40: Rustic House | B40: =COUNTIF(Q5:Q20,"Rustic House") -> 0
A41: Broken Chains | B41: =COUNTIF(Q5:Q20,"Broken Chains") -> 0
A43: Shelter placements
A44: Good Sam | B44: =COUNTIF(O5:O20,"Good Sam") -> 0
A45: Salvation Army | B45: =COUNTIF(O5:O20,"Salvation Army") -> 0
A49: Discharge Analytics
...

Sheet Sheet1
A2: Discharge Analytics
A3: Program outcomes across all processed discharges — updates automatically
A5: 30 | C5: 11.7 days | E5: 0.7 | G5: 0.73 | I5: 0.63
A8: TOTAL DISCHARGES | C8: AVG LENGTH OF STAY | E8: MET DISCHARGE PLAN | G8: OBTAINED ID | I8: OBTAINED SNAP
A11: Length of Stay by Level of Care | G11: Discharges by Referral Source
A12: LOC | B12: Discharges | C12: Avg LOS | G12: Referral Source | H12: Count | I12: % of Total
A13: LOC1 | B13: 9 | C13: 16.3 | G13: OCR | H13: 5 | I13: 0.17
A14: LOC2 | B14: 7 | C14: 10 | G14: MCOT | H14: 5 | I14: 0.17
A15: LOC3 | B15: 3 | C15: 8.7 | G15: Oceans | H15: 7 | I15: 0.23
A16: LOC4 | B16: 0 | C16: 0 | G16: Bayview | H16: 2 | I16: 0.07
A17: LOC5 | B17: 11 | C17: 9.9 | G17: OTHER | H17: 3 | I17: 0.1
G18: CaseMgr | H18: 2 | I18: 0.07
A20: Resources Obtained at Discharge
A21: Resource | B21: Obtained | C21: Rate
A22: Met Discharge Plan | B22: 21 | C22: 0.7
A23: Obtained ID | B23: 22 | C23: 0.73
A24: Obtained Bus Pass | B24: 17 | C24: 0.57
A25: Obtained Clinic Card | B25: 19 | C25: 0.63
A26: Obtained SNAP | B26: 19 | C26: 0.63

Sheet Client Status Board
A1: Client Status Board
A2: Initials, Bed, Case Manager, and Pharmacy pull automatically. Fill in Doctor, Appointment info, Scripts Status + Submitted Date, and Notes manually. This is the sheet to export/upload to Google Sheets.
A4: Member ID | B4: Client Initials | C4: Bed | D4: Referral source | E4: Case Manager | F4: Appointment Status | G4: Doctor | H4: Appointment Time | I4: Appointment Date | J4: Notes | K4: Pharmacy Status | L4: Pharmacy | M4: Med Times | N4: LOC | O4: Admit Date
A5: ='Client Needs Tracker'!A5 -> 102558 | B5: =IF('Client Needs Tracker'!B5="","",UPPER(LEFT(TRIM('Client Needs Tracker'!B5),1))&"."&UPPER(MID('Client Needs Tracker'!B5,FIND("@",SUBSTITUTE('Client Needs Tracker'!B5," ","@",LEN('Client Needs Tracker'!B5)-LEN(SUBSTITUTE('Client Needs Tracker'!B5," ",""))))+1,1))&".") -> J.J. | C5: =IF('Client Needs Tracker'!S5="","",'Client Needs Tracker'!S5) -> M - 1A | D5: =IF('Client Needs Tracker'!G5="","",'Client Needs Tracker'!G5) -> PubDef | E5: =IF('Client Needs Tracker'!F5="","",'Client Needs Tracker'!F5) -> TBD | F5: Requested/Pending | G5: Unknown | H5: 0.36458333 | I5: 46240 | J5: Needs clothes | K5: Submitted/Pending | L5: Genoa | M5: =IF(IF('Inventory - P01'!H16="","",'Inventory - P01'!H16&" | ")&IF('Inventory - P01'!H17="","",'Inventory - P01'!H17&" | ")&IF('Inventory - P01'!H18="","",'Inventory - P01'!H18&" | ")&IF('Inventory - P01'!H19="","",'Inventory - P01'!H19&" | ")&IF('Inventory - P01'!H20="","",'Inventory - P01'!H20&" | ")&IF('Inventory - P01'!H21="","",'Inventory - P01'!H21&" | ")&IF('Inventory - P01'!H22="","",'Inventory - P01'!H22&" | ")&IF('Inventory - P01'!H23="","",'Inventory - P01'!H23&" | ")&IF('Inventory - P01'!H24="","",'Inventory - P01'!H24&" | ")&IF('Inventory - P01'!H25="","",'Inventory - P01'!H25&" | ")&IF('Inventory - P01'!H26="","",'Inventory - P01'!H26&" | ")&IF('Inventory - P01'!H27="","",'Inventory - P01'!H27&" | ")="","",LEFT(IF('Inventory - P01'!H16="","",'Inventory - P01'!H16&" | ")&IF('Inventory - P01'!H17="","",'Inventory - P01'!H17&" | ")&IF('Inventory - P01'!H18="","",'Inventory - P01'!H18&" | ")&IF('Inventory - P01'!H19="","",'Inventory - P01'!H19&" | ")&IF('Inventory - P01'!H20="","",'Inventory - P01'!H20&" | ")&IF('Inventory - P01'!H21="","",'Inventory - P01'!H21&" | ")&IF('Inventory - P01'!H22="","",'Inventory - P01'!H22&" | ")&IF('Inventory - P01'!H23="","",'Inventory - P01'!H23&" | ")&IF('Inventory - P01'!H24="","",'Inventory - P01'!H24&" | ")&IF('Inventory - P01'!H25="","",'Inventory - P01'!H25&" | ")&IF('Inventory - P01'!H26="","",'Inventory - P01'!H26&" | ")&IF('Inventory - P01'!H27="","",'Inventory - P01'!H27&" | "),LEN(IF('Inventory - P01'!H16="","",'Inventory - P01'!H16&" | ")&IF('Inventory - P01'!H17="","",'Inventory - P01'!H17&" | ")&IF('Inventory - P01'!H18="","",'Inventory - P01'!H18&" | ")&IF('Inventory - P01'!H19="","",'Inventory - P01'!H19&" | ")&IF('Inventory - P01'!H20="","",'Inventory - P01'!H20&" | ")&IF('Inventory - P01'!H21="","",'Inventory - P01'!H21&" | ")&IF('Inventory - P01'!H22="","",'Inventory - P01'!H22&" | ")&IF('Inventory - P01'!H23="","",'Inventory - P01'!H23&" | ")&IF('Inventory - P01'!H24="","",'Inventory - P01'!H24&" | ")&IF('Inventory - P01'!H25="","",'Inventory - P01'!H25&" | ")&IF('Inventory - P01'!H26="","",'Inventory - P01'!H26&" | ")&IF('Inventory - P01'!H27="","",'Inventory - P01'!H27&" | "))-3)) -> 8:00 AM / 12:00 PM / 4:00 PM / 8:00 PM | N5: =IF('Client Needs Tracker'!E5="","",'Client Needs Tracker'!E5) -> TBD | O5: =IF('Client Needs Tracker'!C5="","",'Client Needs Tracker'!C5) -> 46228
A6: ='Client Needs Tracker'!A6 -> 3520025 | B6: =IF('Client Needs Tracker'!B6="","",UPPER(LEFT(TRIM('Client Needs Tracker'!B6),1))&"."&UPPER(MID('Client Needs Tracker'!B6,FIND("@",SUBSTITUTE('Client Needs Tracker'!B6," ","@",LEN('Client Needs Tracker'!B6)-LEN(SUBSTITUTE('Client Needs Tracker'!B6," ",""))))+1,1))&".") -> Y.J. | C6: =IF('Client Needs Tracker'!S6="","",'Client Needs Tracker'!S6) -> M - 1B | D6: =IF('Client Needs Tracker'!G6="","",'Client Needs Tracker'!G6) -> Bayview | E6: =IF('Client Needs Tracker'!F6="","",'Client Needs Tracker'!F6) | F6: Scheduled | G6: Destiny | H6: 0.38541667 | I6: 46244 | K6: Picked Up | L6: HEB | M6: =IF(IF('Inventory - P02'!H16="","",'Inventory - P02'!H16&" | ")&IF('Inventory - P02'!H17="","",'Inventory - P02'!H17&" | ")&IF('Inventory - P02'!H18="","",'Inventory - P02'!H18&" | ")&IF('Inventory - P02'!H19="","",'Inventory - P02'!H19&" | ")&IF('Inventory - P02'!H20="","",'Inventory - P02'!H20&" | ")&IF('Inventory - P02'!H21="","",'Inventory - P02'!H21&" | ")&IF('Inventory - P02'!H22="","",'Inventory - P02'!H22&" | ")&IF('Inventory - P02'!H23="","",'Inventory - P02'!H23&" | ")&IF('Inventory - P02'!H24="","",'Inventory - P02'!H24&" | ")&IF('Inventory - P02'!H25="","",'Inventory - P02'!H25&" | ")&IF('Inventory - P02'!H26="","",'Inventory - P02'!H26&" | ")&IF('Inventory - P02'!H27="","",'Inventory - P02'!H27&" | ")="","",LEFT(IF('Inventory - P02'!H16="","",'Inventory - P02'!H16&" | ")&IF('Inventory - P02'!H17="","",'Inventory - P02'!H17&" | ")&IF('Inventory - P02'!H18="","",'Inventory - P02'!H18&" | ")&IF('Inventory - P02'!H19="","",'Inventory - P02'!H19&" | ")&IF('Inventory - P02'!H20="","",'Inventory - P02'!H20&" | ")&IF('Inventory - P02'!H21="","",'Inventory - P02'!H21&" | ")&IF('Inventory - P02'!H22="","",'Inventory - P02'!H22&" | ")&IF('Inventory - P02'!H23="","",'Inventory - P02'!H23&" | ")&IF('Inventory - P02'!H24="","",'Inventory - P02'!H24&" | ")&IF('Inventory - P02'!H25="","",'Inventory - P02'!H25&" | ")&IF('Inventory - P02'!H26="","",'Inventory - P02'!H26&" | ")&IF('Inventory - P02'!H27="","",'Inventory - P02'!H27&" | "),LEN(IF('Inventory - P02'!H16="","",'Inventory - P02'!H16&" | ")&IF('Inventory - P02'!H17="","",'Inventory - P02'!H17&" | ")&IF('Inventory - P02'!H18="","",'Inventory - P02'!H18&" | ")&IF('Inventory - P02'!H19="","",'Inventory - P02'!H19&" | ")&IF('Inventory - P02'!H20="","",'Inventory - P02'!H20&" | ")&IF('Inventory - P02'!H21="","",'Inventory - P02'!H21&" | ")&IF('Inventory - P02'!H22="","",'Inventory - P02'!H22&" | ")&IF('Inventory - P02'!H23="","",'Inventory - P02'!H23&" | ")&IF('Inventory - P02'!H24="","",'Inventory - P02'!H24&" | ")&IF('Inventory - P02'!H25="","",'Inventory - P02'!H25&" | ")&IF('Inventory - P02'!H26="","",'Inventory - P02'!H26&" | ")&IF('Inventory - P02'!H27="","",'Inventory - P02'!H27&" | "))-3)) -> 8:00 AM / 8:00 PM | N6: =IF('Client Needs Tracker'!E6="","",'Client Needs Tracker'!E6) -> LOC2 | O6: =IF('Client Needs Tracker'!C6="","",'Client Needs Tracker'!C6) -> 46240
A7: ='Client Needs Tracker'!A7 -> 0 | B7: =IF('Client Needs Tracker'!B7="","",UPPER(LEFT(TRIM('Client Needs Tracker'!B7),1))&"."&UPPER(MID('Client Needs Tracker'!B7,FIND("@",SUBSTITUTE('Client Needs Tracker'!B7," ","@",LEN('Client Needs Tracker'!B7)-LEN(SUBSTITUTE('Client Needs Tracker'!B7," ",""))))+1,1))&".") | C7: =IF('Client Needs Tracker'!S7="","",'Client Needs Tracker'!S7) -> M - 2A | D7: =IF('Client Needs Tracker'!G7="","",'Client Needs Tracker'!G7) | E7: =IF('Client Needs Tracker'!F7="","",'Client Needs Tracker'!F7) | M7: =IF(IF('Inventory - P03'!H16="","",'Inventory - P03'!H16&" | ")&IF('Inventory - P03'!H17="","",'Inventory - P03'!H17&" | ")&IF('Inventory - P03'!H18="","",'Inventory - P03'!H18&" | ")&IF('Inventory - P03'!H19="","",'Inventory - P03'!H19&" | ")&IF('Inventory - P03'!H20="","",'Inventory - P03'!H20&" | ")&IF('Inventory - P03'!H21="","",'Inventory - P03'!H21&" | ")&IF('Inventory - P03'!H22="","",'Inventory - P03'!H22&" | ")&IF('Inventory - P03'!H23="","",'Inventory - P03'!H23&" | ")&IF('Inventory - P03'!H24="","",'Inventory - P03'!H24&" | ")&IF('Inventory - P03'!H25="","",'Inventory - P03'!H25&" | ")&IF('Inventory - P03'!H26="","",'Inventory - P03'!H26&" | ")&IF('Inventory - P03'!H27="","",'Inventory - P03'!H27&" | ")="","",LEFT(IF('Inventory - P03'!H16="","",'Inventory - P03'!H16&" | ")&IF('Inventory - P03'!H17="","",'Inventory - P03'!H17&" | ")&IF('Inventory - P03'!H18="","",'Inventory - P03'!H18&" | ")&IF('Inventory - P03'!H19="","",'Inventory - P03'!H19&" | ")&IF('Inventory - P03'!H20="","",'Inventory - P03'!H20&" | ")&IF('Inventory - P03'!H21="","",'Inventory - P03'!H21&" | ")&IF('Inventory - P03'!H22="","",'Inventory - P03'!H22&" | ")&IF('Inventory - P03'!H23="","",'Inventory - P03'!H23&" | ")&IF('Inventory - P03'!H24="","",'Inventory - P03'!H24&" | ")&IF('Inventory - P03'!H25="","",'Inventory - P03'!H25&" | ")&IF('Inventory - P03'!H26="","",'Inventory - P03'!H26&" | ")&IF('Inventory - P03'!H27="","",'Inventory - P03'!H27&" | "),LEN(IF('Inventory - P03'!H16="","",'Inventory - P03'!H16&" | ")&IF('Inventory - P03'!H17="","",'Inventory - P03'!H17&" | ")&IF('Inventory - P03'!H18="","",'Inventory - P03'!H18&" | ")&IF('Inventory - P03'!H19="","",'Inventory - P03'!H19&" | ")&IF('Inventory - P03'!H20="","",'Inventory - P03'!H20&" | ")&IF('Inventory - P03'!H21="","",'Inventory - P03'!H21&" | ")&IF('Inventory - P03'!H22="","",'Inventory - P03'!H22&" | ")&IF('Inventory - P03'!H23="","",'Inventory - P03'!H23&" | ")&IF('Inventory - P03'!H24="","",'Inventory - P03'!H24&" | ")&IF('Inventory - P03'!H25="","",'Inventory - P03'!H25&" | ")&IF('Inventory - P03'!H26="","",'Inventory - P03'!H26&" | ")&IF('Inventory - P03'!H27="","",'Inventory - P03'!H27&" | "))-3)) | N7: =IF('Client Needs Tracker'!E7="","",'Client Needs Tracker'!E7) | O7: =IF('Client Needs Tracker'!C7="","",'Client Needs Tracker'!C7)
A8: ='Client Needs Tracker'!A8 -> 0 | B8: =IF('Client Needs Tracker'!B8="","",UPPER(LEFT(TRIM('Client Needs Tracker'!B8),1))&"."&UPPER(MID('Client Needs Tracker'!B8,FIND("@",SUBSTITUTE('Client Needs Tracker'!B8," ","@",LEN('Client Needs Tracker'!B8)-LEN(SUBSTITUTE('Client Needs Tracker'!B8," ",""))))+1,1))&".") | C8: =IF('Client Needs Tracker'!S8="","",'Client Needs Tracker'!S8) -> M - 2B | D8: =IF('Client Needs Tracker'!G8="","",'Client Needs Tracker'!G8) | E8: =IF('Client Needs Tracker'!F8="","",'Client Needs Tracker'!F8) | F8: Scheduled | K8: Submitted/Pending | M8: =IF(IF('Inventory - P04'!H16="","",'Inventory - P04'!H16&" | ")&IF('Inventory - P04'!H17="","",'Inventory - P04'!H17&" | ")&IF('Inventory - P04'!H18="","",'Inventory - P04'!H18&" | ")&IF('Inventory - P04'!H19="","",'Inventory - P04'!H19&" | ")&IF('Inventory - P04'!H20="","",'Inventory - P04'!H20&" | ")&IF('Inventory - P04'!H21="","",'Inventory - P04'!H21&" | ")&IF('Inventory - P04'!H22="","",'Inventory - P04'!H22&" | ")&IF('Inventory - P04'!H23="","",'Inventory - P04'!H23&" | ")&IF('Inventory - P04'!H24="","",'Inventory - P04'!H24&" | ")&IF('Inventory - P04'!H25="","",'Inventory - P04'!H25&" | ")&IF('Inventory - P04'!H26="","",'Inventory - P04'!H26&" | ")&IF('Inventory - P04'!H27="","",'Inventory - P04'!H27&" | ")="","",LEFT(IF('Inventory - P04'!H16="","",'Inventory - P04'!H16&" | ")&IF('Inventory - P04'!H17="","",'Inventory - P04'!H17&" | ")&IF('Inventory - P04'!H18="","",'Inventory - P04'!H18&" | ")&IF('Inventory - P04'!H19="","",'Inventory - P04'!H19&" | ")&IF('Inventory - P04'!H20="","",'Inventory - P04'!H20&" | ")&IF('Inventory - P04'!H21="","",'Inventory - P04'!H21&" | ")&IF('Inventory - P04'!H22="","",'Inventory - P04'!H22&" | ")&IF('Inventory - P04'!H23="","",'Inventory - P04'!H23&" | ")&IF('Inventory - P04'!H24="","",'Inventory - P04'!H24&" | ")&IF('Inventory - P04'!H25="","",'Inventory - P04'!H25&" | ")&IF('Inventory - P04'!H26="","",'Inventory - P04'!H26&" | ")&IF('Inventory - P04'!H27="","",'Inventory - P04'!H27&" | "),LEN(IF('Inventory - P04'!H16="","",'Inventory - P04'!H16&" | ")&IF('Inventory - P04'!H17="","",'Inventory - P04'!H17&" | ")&IF('Inventory - P04'!H18="","",'Inventory - P04'!H18&" | ")&IF('Inventory - P04'!H19="","",'Inventory - P04'!H19&" | ")&IF('Inventory - P04'!H20="","",'Inventory - P04'!H20&" | ")&IF('Inventory - P04'!H21="","",'Inventory - P04'!H21&" | ")&IF('Inventory - P04'!H22="","",'Inventory - P04'!H22&" | ")&IF('Inventory - P04'!H23="","",'Inventory - P04'!H23&" | ")&IF('Inventory - P04'!H24="","",'Inventory - P04'!H24&" | ")&IF('Inventory - P04'!H25="","",'Inventory - P04'!H25&" | ")&IF('Inventory - P04'!H26="","",'Inventory - P04'!H26&" | ")&IF('Inventory - P04'!H27="","",'Inventory - P04'!H27&" | "))-3)) | N8: =IF('Client Needs Tracker'!E8="","",'Client Needs Tracker'!E8) | O8: =IF('Client Needs Tracker'!C8="","",'Client Needs Tracker'!C8)
A9: ='Client Needs Tracker'!A9 -> 0 | B9: =IF('Client Needs Tracker'!B9="","",UPPER(LEFT(TRIM('Client Needs Tracker'!B9),1))&"."&UPPER(MID('Client Needs Tracker'!B9,FIND("@",SUBSTITUTE('Client Needs Tracker'!B9," ","@",LEN('Client Needs Tracker'!B9)-LEN(SUBSTITUTE('Client Needs Tracker'!B9," ",""))))+1,1))&".") | C9: =IF('Client Needs Tracker'!S9="","",'Client Needs Tracker'!S9) -> M - 3A | D9: =IF('Client Needs Tracker'!G9="","",'Client Needs Tracker'!G9) | E9: =IF('Client Needs Tracker'!F9="","",'Client Needs Tracker'!F9) | F9: Scheduled | K9: Submitted/Pending | M9: =IF(IF('Inventory - P05'!H16="","",'Inventory - P05'!H16&" | ")&IF('Inventory - P05'!H17="","",'Inventory - P05'!H17&" | ")&IF('Inventory - P05'!H18="","",'Inventory - P05'!H18&" | ")&IF('Inventory - P05'!H19="","",'Inventory - P05'!H19&" | ")&IF('Inventory - P05'!H20="","",'Inventory - P05'!H20&" | ")&IF('Inventory - P05'!H21="","",'Inventory - P05'!H21&" | ")&IF('Inventory - P05'!H22="","",'Inventory - P05'!H22&" | ")&IF('Inventory - P05'!H23="","",'Inventory - P05'!H23&" | ")&IF('Inventory - P05'!H24="","",'Inventory - P05'!H24&" | ")&IF('Inventory - P05'!H25="","",'Inventory - P05'!H25&" | ")&IF('Inventory - P05'!H26="","",'Inventory - P05'!H26&" | ")&IF('Inventory - P05'!H27="","",'Inventory - P05'!H27&" | ")="","",LEFT(IF('Inventory - P05'!H16="","",'Inventory - P05'!H16&" | ")&IF('Inventory - P05'!H17="","",'Inventory - P05'!H17&" | ")&IF('Inventory - P05'!H18="","",'Inventory - P05'!H18&" | ")&IF('Inventory - P05'!H19="","",'Inventory - P05'!H19&" | ")&IF('Inventory - P05'!H20="","",'Inventory - P05'!H20&" | ")&IF('Inventory - P05'!H21="","",'Inventory - P05'!H21&" | ")&IF('Inventory - P05'!H22="","",'Inventory - P05'!H22&" | ")&IF('Inventory - P05'!H23="","",'Inventory - P05'!H23&" | ")&IF('Inventory - P05'!H24="","",'Inventory - P05'!H24&" | ")&IF('Inventory - P05'!H25="","",'Inventory - P05'!H25&" | ")&IF('Inventory - P05'!H26="","",'Inventory - P05'!H26&" | ")&IF('Inventory - P05'!H27="","",'Inventory - P05'!H27&" | "),LEN(IF('Inventory - P05'!H16="","",'Inventory - P05'!H16&" | ")&IF('Inventory - P05'!H17="","",'Inventory - P05'!H17&" | ")&IF('Inventory - P05'!H18="","",'Inventory - P05'!H18&" | ")&IF('Inventory - P05'!H19="","",'Inventory - P05'!H19&" | ")&IF('Inventory - P05'!H20="","",'Inventory - P05'!H20&" | ")&IF('Inventory - P05'!H21="","",'Inventory - P05'!H21&" | ")&IF('Inventory - P05'!H22="","",'Inventory - P05'!H22&" | ")&IF('Inventory - P05'!H23="","",'Inventory - P05'!H23&" | ")&IF('Inventory - P05'!H24="","",'Inventory - P05'!H24&" | ")&IF('Inventory - P05'!H25="","",'Inventory - P05'!H25&" | ")&IF('Inventory - P05'!H26="","",'Inventory - P05'!H26&" | ")&IF('Inventory - P05'!H27="","",'Inventory - P05'!H27&" | "))-3)) | N9: =IF('Client Needs Tracker'!E9="","",'Client Needs Tracker'!E9) | O9: =IF('Client Needs Tracker'!C9="","",'Client Needs Tracker'!C9)
A10: ='Client Needs Tracker'!A10 -> 0 | B10: =IF('Client Needs Tracker'!B10="","",UPPER(LEFT(TRIM('Client Needs Tracker'!B10),1))&"."&UPPER(MID('Client Needs Tracker'!B10,FIND("@",SUBSTITUTE('Client Needs Tracker'!B10," ","@",LEN('Client Needs Tracker'!B10)-LEN(SUBSTITUTE('Client Needs Tracker'!B10," ",""))))+1,1))&".") | C10: =IF('Client Needs Tracker'!S10="","",'Client Needs Tracker'!S10) -> M - 3B | D10: =IF('Client Needs Tracker'!G10="","",'Client Needs Tracker'!G10) | E10: =IF('Client Needs Tracker'!F10="","",'Client Needs Tracker'!F10) | F10: Scheduled | K10: Submitted/Pending | M10: =IF(IF('Inventory - P06'!H16="","",'Inventory - P06'!H16&" | ")&IF('Inventory - P06'!H17="","",'Inventory - P06'!H17&" | ")&IF('Inventory - P06'!H18="","",'Inventory - P06'!H18&" | ")&IF('Inventory - P06'!H19="","",'Inventory - P06'!H19&" | ")&IF('Inventory - P06'!H20="","",'Inventory - P06'!H20&" | ")&IF('Inventory - P06'!H21="","",'Inventory - P06'!H21&" | ")&IF('Inventory - P06'!H22="","",'Inventory - P06'!H22&" | ")&IF('Inventory - P06'!H23="","",'Inventory - P06'!H23&" | ")&IF('Inventory - P06'!H24="","",'Inventory - P06'!H24&" | ")&IF('Inventory - P06'!H25="","",'Inventory - P06'!H25&" | ")&IF('Inventory - P06'!H26="","",'Inventory - P06'!H26&" | ")&IF('Inventory - P06'!H27="","",'Inventory - P06'!H27&" | ")="","",LEFT(IF('Inventory - P06'!H16="","",'Inventory - P06'!H16&" | ")&IF('Inventory - P06'!H17="","",'Inventory - P06'!H17&" | ")&IF('Inventory - P06'!H18="","",'Inventory - P06'!H18&" | ")&IF('Inventory - P06'!H19="","",'Inventory - P06'!H19&" | ")&IF('Inventory - P06'!H20="","",'Inventory - P06'!H20&" | ")&IF('Inventory - P06'!H21="","",'Inventory - P06'!H21&" | ")&IF('Inventory - P06'!H22="","",'Inventory - P06'!H22&" | ")&IF('Inventory - P06'!H23="","",'Inventory - P06'!H23&" | ")&IF('Inventory - P06'!H24="","",'Inventory - P06'!H24&" | ")&IF('Inventory - P06'!H25="","",'Inventory - P06'!H25&" | ")&IF('Inventory - P06'!H26="","",'Inventory - P06'!H26&" | ")&IF('Inventory - P06'!H27="","",'Inventory - P06'!H27&" | "),LEN(IF('Inventory - P06'!H16="","",'Inventory - P06'!H16&" | ")&IF('Inventory - P06'!H17="","",'Inventory - P06'!H17&" | ")&IF('Inventory - P06'!H18="","",'Inventory - P06'!H18&" | ")&IF('Inventory - P06'!H19="","",'Inventory - P06'!H19&" | ")&IF('Inventory - P06'!H20="","",'Inventory - P06'!H20&" | ")&IF('Inventory - P06'!H21="","",'Inventory - P06'!H21&" | ")&IF('Inventory - P06'!H22="","",'Inventory - P06'!H22&" | ")&IF('Inventory - P06'!H23="","",'Inventory - P06'!H23&" | ")&IF('Inventory - P06'!H24="","",'Inventory - P06'!H24&" | ")&IF('Inventory - P06'!H25="","",'Inventory - P06'!H25&" | ")&IF('Inventory - P06'!H26="","",'Inventory - P06'!H26&" | ")&IF('Inventory - P06'!H27="","",'Inventory - P06'!H27&" | "))-3)) | N10: =IF('Client Needs Tracker'!E10="","",'Client Needs Tracker'!E10) | O10: =IF('Client Needs Tracker'!C10="","",'Client Needs Tracker'!C10)
A11: ='Client Needs Tracker'!A11 -> 0 | B11: =IF('Client Needs Tracker'!B11="","",UPPER(LEFT(TRIM('Client Needs Tracker'!B11),1))&"."&UPPER(MID('Client Needs Tracker'!B11,FIND("@",SUBSTITUTE('Client Needs Tracker'!B11," ","@",LEN('Client Needs Tracker'!B11)-LEN(SUBSTITUTE('Client Needs Tracker'!B11," ",""))))+1,1))&".") | C11: =IF('Client Needs Tracker'!S11="","",'Client Needs Tracker'!S11) -> M - 4A | D11: =IF('Client Needs Tracker'!G11="","",'Client Needs Tracker'!G11) | E11: =IF('Client Needs Tracker'!F11="","",'Client Needs Tracker'!F11) | F11: Scheduled | K11: Submitted/Pending | M11: =IF(IF('Inventory - P07'!H16="","",'Inventory - P07'!H16&" | ")&IF('Inventory - P07'!H17="","",'Inventory - P07'!H17&" | ")&IF('Inventory - P07'!H18="","",'Inventory - P07'!H18&" | ")&IF('Inventory - P07'!H19="","",'Inventory - P07'!H19&" | ")&IF('Inventory - P07'!H20="","",'Inventory - P07'!H20&" | ")&IF('Inventory - P07'!H21="","",'Inventory - P07'!H21&" | ")&IF('Inventory - P07'!H22="","",'Inventory - P07'!H22&" | ")&IF('Inventory - P07'!H23="","",'Inventory - P07'!H23&" | ")&IF('Inventory - P07'!H24="","",'Inventory - P07'!H24&" | ")&IF('Inventory - P07'!H25="","",'Inventory - P07'!H25&" | ")&IF('Inventory - P07'!H26="","",'Inventory - P07'!H26&" | ")&IF('Inventory - P07'!H27="","",'Inventory - P07'!H27&" | ")="","",LEFT(IF('Inventory - P07'!H16="","",'Inventory - P07'!H16&" | ")&IF('Inventory - P07'!H17="","",'Inventory - P07'!H17&" | ")&IF('Inventory - P07'!H18="","",'Inventory - P07'!H18&" | ")&IF('Inventory - P07'!H19="","",'Inventory - P07'!H19&" | ")&IF('Inventory - P07'!H20="","",'Inventory - P07'!H20&" | ")&IF('Inventory - P07'!H21="","",'Inventory - P07'!H21&" | ")&IF('Inventory - P07'!H22="","",'Inventory - P07'!H22&" | ")&IF('Inventory - P07'!H23="","",'Inventory - P07'!H23&" | ")&IF('Inventory - P07'!H24="","",'Inventory - P07'!H24&" | ")&IF('Inventory - P07'!H25="","",'Inventory - P07'!H25&" | ")&IF('Inventory - P07'!H26="","",'Inventory - P07'!H26&" | ")&IF('Inventory - P07'!H27="","",'Inventory - P07'!H27&" | "),LEN(IF('Inventory - P07'!H16="","",'Inventory - P07'!H16&" | ")&IF('Inventory - P07'!H17="","",'Inventory - P07'!H17&" | ")&IF('Inventory - P07'!H18="","",'Inventory - P07'!H18&" | ")&IF('Inventory - P07'!H19="","",'Inventory - P07'!H19&" | ")&IF('Inventory - P07'!H20="","",'Inventory - P07'!H20&" | ")&IF('Inventory - P07'!H21="","",'Inventory - P07'!H21&" | ")&IF('Inventory - P07'!H22="","",'Inventory - P07'!H22&" | ")&IF('Inventory - P07'!H23="","",'Inventory - P07'!H23&" | ")&IF('Inventory - P07'!H24="","",'Inventory - P07'!H24&" | ")&IF('Inventory - P07'!H25="","",'Inventory - P07'!H25&" | ")&IF('Inventory - P07'!H26="","",'Inventory - P07'!H26&" | ")&IF('Inventory - P07'!H27="","",'Inventory - P07'!H27&" | "))-3)) | N11: =IF('Client Needs Tracker'!E11="","",'Client Needs Tracker'!E11) | O11: =IF('Client Needs Tracker'!C11="","",'Client Needs Tracker'!C11)
A12: ='Client Needs Tracker'!A12 -> 0 | B12: =IF('Client Needs Tracker'!B12="","",UPPER(LEFT(TRIM('Client Needs Tracker'!B12),1))&"."&UPPER(MID('Client Needs Tracker'!B12,FIND("@",SUBSTITUTE('Client Needs Tracker'!B12," ","@",LEN('Client Needs Tracker'!B12)-LEN(SUBSTITUTE('Client Needs Tracker'!B12," ",""))))+1,1))&".") | C12: =IF('Client Needs Tracker'!S12="","",'Client Needs Tracker'!S12) -> M - 4B | D12: =IF('Client Needs Tracker'!G12="","",'Client Needs Tracker'!G12) | E12: =IF('Client Needs Tracker'!F12="","",'Client Needs Tracker'!F12) | F12: Scheduled | K12: Submitted/Pending | M12: =IF(IF('Inventory - P08'!H16="","",'Inventory - P08'!H16&" | ")&IF('Inventory - P08'!H17="","",'Inventory - P08'!H17&" | ")&IF('Inventory - P08'!H18="","",'Inventory - P08'!H18&" | ")&IF('Inventory - P08'!H19="","",'Inventory - P08'!H19&" | ")&IF('Inventory - P08'!H20="","",'Inventory - P08'!H20&" | ")&IF('Inventory - P08'!H21="","",'Inventory - P08'!H21&" | ")&IF('Inventory - P08'!H22="","",'Inventory - P08'!H22&" | ")&IF('Inventory - P08'!H23="","",'Inventory - P08'!H23&" | ")&IF('Inventory - P08'!H24="","",'Inventory - P08'!H24&" | ")&IF('Inventory - P08'!H25="","",'Inventory - P08'!H25&" | ")&IF('Inventory - P08'!H26="","",'Inventory - P08'!H26&" | ")&IF('Inventory - P08'!H27="","",'Inventory - P08'!H27&" | ")="","",LEFT(IF('Inventory - P08'!H16="","",'Inventory - P08'!H16&" | ")&IF('Inventory - P08'!H17="","",'Inventory - P08'!H17&" | ")&IF('Inventory - P08'!H18="","",'Inventory - P08'!H18&" | ")&IF('Inventory - P08'!H19="","",'Inventory - P08'!H19&" | ")&IF('Inventory - P08'!H20="","",'Inventory - P08'!H20&" | ")&IF('Inventory - P08'!H21="","",'Inventory - P08'!H21&" | ")&IF('Inventory - P08'!H22="","",'Inventory - P08'!H22&" | ")&IF('Inventory - P08'!H23="","",'Inventory - P08'!H23&" | ")&IF('Inventory - P08'!H24="","",'Inventory - P08'!H24&" | ")&IF('Inventory - P08'!H25="","",'Inventory - P08'!H25&" | ")&IF('Inventory - P08'!H26="","",'Inventory - P08'!H26&" | ")&IF('Inventory - P08'!H27="","",'Inventory - P08'!H27&" | "),LEN(IF('Inventory - P08'!H16="","",'Inventory - P08'!H16&" | ")&IF('Inventory - P08'!H17="","",'Inventory - P08'!H17&" | ")&IF('Inventory - P08'!H18="","",'Inventory - P08'!H18&" | ")&IF('Inventory - P08'!H19="","",'Inventory - P08'!H19&" | ")&IF('Inventory - P08'!H20="","",'Inventory - P08'!H20&" | ")&IF('Inventory - P08'!H21="","",'Inventory - P08'!H21&" | ")&IF('Inventory - P08'!H22="","",'Inventory - P08'!H22&" | ")&IF('Inventory - P08'!H23="","",'Inventory - P08'!H23&" | ")&IF('Inventory - P08'!H24="","",'Inventory - P08'!H24&" | ")&IF('Inventory - P08'!H25="","",'Inventory - P08'!H25&" | ")&IF('Inventory - P08'!H26="","",'Inventory - P08'!H26&" | ")&IF('Inventory - P08'!H27="","",'Inventory - P08'!H27&" | "))-3)) | N12: =IF('Client Needs Tracker'!E12="","",'Client Needs Tracker'!E12) | O12: =IF('Client Needs Tracker'!C12="","",'Client Needs Tracker'!C12)
A13: ='Client Needs Tracker'!A13 -> 102558 | B13: =IF('Client Needs Tracker'!B13="","",UPPER(LEFT(TRIM('Client Needs Tracker'!B13),1))&"."&UPPER(MID('Client Needs Tracker'!B13,FIND("@",SUBSTITUTE('Client Needs Tracker'!B13," ","@",LEN('Client Needs Tracker'!B13)-LEN(SUBSTITUTE('Client Needs Tracker'!B13," ",""))))+1,1))&".") -> B.H. | C13: =IF('Client Needs Tracker'!S13="","",'Client Needs Tracker'!S13) -> F - 1A | D13: =IF('Client Needs Tracker'!G13="","",'Client Needs Tracker'!G13) -> Bayview | M13: =IF(IF('Inventory - P09'!H16="","",'Inventory - P09'!H16&" | ")&IF('Inventory - P09'!H17="","",'Inventory - P09'!H17&" | ")&IF('Inventory - P09'!H18="","",'Inventory - P09'!H18&" | ")&IF('Inventory - P09'!H19="","",'Inventory - P09'!H19&" | ")&IF('Inventory - P09'!H20="","",'Inventory - P09'!H20&" | ")&IF('Inventory - P09'!H21="","",'Inventory - P09'!H21&" | ")&IF('Inventory - P09'!H22="","",'Inventory - P09'!H22&" | ")&IF('Inventory - P09'!H23="","",'Inventory - P09'!H23&" | ")&IF('Inventory - P09'!H24="","",'Inventory - P09'!H24&" | ")&IF('Inventory - P09'!H25="","",'Inventory - P09'!H25&" | ")&IF('Inventory - P09'!H26="","",'Inventory - P09'!H26&" | ")&IF('Inventory - P09'!H27="","",'Inventory - P09'!H27&" | ")="","",LEFT(IF('Inventory - P09'!H16="","",'Inventory - P09'!H16&" | ")&IF('Inventory - P09'!H17="","",'Inventory - P09'!H17&" | ")&IF('Inventory - P09'!H18="","",'Inventory - P09'!H18&" | ")&IF('Inventory - P09'!H19="","",'Inventory - P09'!H19&" | ")&IF('Inventory - P09'!H20="","",'Inventory - P09'!H20&" | ")&IF('Inventory - P09'!H21="","",'Inventory - P09'!H21&" | ")&IF('Inventory - P09'!H22="","",'Inventory - P09'!H22&" | ")&IF('Inventory - P09'!H23="","",'Inventory - P09'!H23&" | ")&IF('Inventory - P09'!H24="","",'Inventory - P09'!H24&" | ")&IF('Inventory - P09'!H25="","",'Inventory - P09'!H25&" | ")&IF('Inventory - P09'!H26="","",'Inventory - P09'!H26&" | ")&IF('Inventory - P09'!H27="","",'Inventory - P09'!H27&" | "),LEN(IF('Inventory - P09'!H16="","",'Inventory - P09'!H16&" | ")&IF('Inventory - P09'!H17="","",'Inventory - P09'!H17&" | ")&IF('Inventory - P09'!H18="","",'Inventory - P09'!H18&" | ")&IF('Inventory - P09'!H19="","",'Inventory - P09'!H19&" | ")&IF('Inventory - P09'!H20="","",'Inventory - P09'!H20&" | ")&IF('Inventory - P09'!H21="","",'Inventory - P09'!H21&" | ")&IF('Inventory - P09'!H22="","",'Inventory - P09'!H22&" | ")&IF('Inventory - P09'!H23="","",'Inventory - P09'!H23&" | ")&IF('Inventory - P09'!H24="","",'Inventory - P09'!H24&" | ")&IF('Inventory - P09'!H25="","",'Inventory - P09'!H25&" | ")&IF('Inventory - P09'!H26="","",'Inventory - P09'!H26&" | ")&IF('Inventory - P09'!H27="","",'Inventory - P09'!H27&" | "))-3)) | N13: =IF('Client Needs Tracker'!E13="","",'Client Needs Tracker'!E13) -> LOC3 | O13: =IF('Client Needs Tracker'!C13="","",'Client Needs Tracker'!C13) -> 46223
A14: ='Client Needs Tracker'!A14 -> 10223 | B14: =IF('Client Needs Tracker'!B14="","",UPPER(LEFT(TRIM('Client Needs Tracker'!B14),1))&"."&UPPER(MID('Client Needs Tracker'!B14,FIND("@",SUBSTITUTE('Client Needs Tracker'!B14," ","@",LEN('Client Needs Tracker'!B14)-LEN(SUBSTITUTE('Client Needs Tracker'!B14," ",""))))+1,1))&".") -> L.L. | C14: =IF('Client Needs Tracker'!S14="","",'Client Needs Tracker'!S14) -> F - 1B | D14: =IF('Client Needs Tracker'!G14="","",'Client Needs Tracker'!G14) | E14: =IF('Client Needs Tracker'!F14="","",'Client Needs Tracker'!F14) | F14: Scheduled | K14: Submitted/Pending | M14: =IF(IF('Inventory - P10'!H16="","",'Inventory - P10'!H16&" | ")&IF('Inventory - P10'!H17="","",'Inventory - P10'!H17&" | ")&IF('Inventory - P10'!H18="","",'Inventory - P10'!H18&" | ")&IF('Inventory - P10'!H19="","",'Inventory - P10'!H19&" | ")&IF('Inventory - P10'!H20="","",'Inventory - P10'!H20&" | ")&IF('Inventory - P10'!H21="","",'Inventory - P10'!H21&" | ")&IF('Inventory - P10'!H22="","",'Inventory - P10'!H22&" | ")&IF('Inventory - P10'!H23="","",'Inventory - P10'!H23&" | ")&IF('Inventory - P10'!H24="","",'Inventory - P10'!H24&" | ")&IF('Inventory - P10'!H25="","",'Inventory - P10'!H25&" | ")&IF('Inventory - P10'!H26="","",'Inventory - P10'!H26&" | ")&IF('Inventory - P10'!H27="","",'Inventory - P10'!H27&" | ")="","",LEFT(IF('Inventory - P10'!H16="","",'Inventory - P10'!H16&" | ")&IF('Inventory - P10'!H17="","",'Inventory - P10'!H17&" | ")&IF('Inventory - P10'!H18="","",'Inventory - P10'!H18&" | ")&IF('Inventory - P10'!H19="","",'Inventory - P10'!H19&" | ")&IF('Inventory - P10'!H20="","",'Inventory - P10'!H20&" | ")&IF('Inventory - P10'!H21="","",'Inventory - P10'!H21&" | ")&IF('Inventory - P10'!H22="","",'Inventory - P10'!H22&" | ")&IF('Inventory - P10'!H23="","",'Inventory - P10'!H23&" | ")&IF('Inventory - P10'!H24="","",'Inventory - P10'!H24&" | ")&IF('Inventory - P10'!H25="","",'Inventory - P10'!H25&" | ")&IF('Inventory - P10'!H26="","",'Inventory - P10'!H26&" | ")&IF('Inventory - P10'!H27="","",'Inventory - P10'!H27&" | "),LEN(IF('Inventory - P10'!H16="","",'Inventory - P10'!H16&" | ")&IF('Inventory - P10'!H17="","",'Inventory - P10'!H17&" | ")&IF('Inventory - P10'!H18="","",'Inventory - P10'!H18&" | ")&IF('Inventory - P10'!H19="","",'Inventory - P10'!H19&" | ")&IF('Inventory - P10'!H20="","",'Inventory - P10'!H20&" | ")&IF('Inventory - P10'!H21="","",'Inventory - P10'!H21&" | ")&IF('Inventory - P10'!H22="","",'Inventory - P10'!H22&" | ")&IF('Inventory - P10'!H23="","",'Inventory - P10'!H23&" | ")&IF('Inventory - P10'!H24="","",'Inventory - P10'!H24&" | ")&IF('Inventory - P10'!H25="","",'Inventory - P10'!H25&" | ")&IF('Inventory - P10'!H26="","",'Inventory - P10'!H26&" | ")&IF('Inventory - P10'!H27="","",'Inventory - P10'!H27&" | "))-3)) | N14: =IF('Client Needs Tracker'!E14="","",'Client Needs Tracker'!E14) | O14: =IF('Client Needs Tracker'!C14="","",'Client Needs Tracker'!C14) -> 46231
A15: ='Client Needs Tracker'!A15 -> 10101010 | B15: =IF('Client Needs Tracker'!B15="","",UPPER(LEFT(TRIM('Client Needs Tracker'!B15),1))&"."&UPPER(MID('Client Needs Tracker'!B15,FIND("@",SUBSTITUTE('Client Needs Tracker'!B15," ","@",LEN('Client Needs Tracker'!B15)-LEN(SUBSTITUTE('Client Needs Tracker'!B15," ",""))))+1,1))&".") -> B.B. | C15: =IF('Client Needs Tracker'!S15="","",'Client Needs Tracker'!S15) -> F - 2A | D15: =IF('Client Needs Tracker'!G15="","",'Client Needs Tracker'!G15) | E15: =IF('Client Needs Tracker'!F15="","",'Client Needs Tracker'!F15) | F15: Scheduled | K15: Submitted/Pending | M15: =IF(IF('Inventory - P11'!H16="","",'Inventory - P11'!H16&" | ")&IF('Inventory - P11'!H17="","",'Inventory - P11'!H17&" | ")&IF('Inventory - P11'!H18="","",'Inventory - P11'!H18&" | ")&IF('Inventory - P11'!H19="","",'Inventory - P11'!H19&" | ")&IF('Inventory - P11'!H20="","",'Inventory - P11'!H20&" | ")&IF('Inventory - P11'!H21="","",'Inventory - P11'!H21&" | ")&IF('Inventory - P11'!H22="","",'Inventory - P11'!H22&" | ")&IF('Inventory - P11'!H23="","",'Inventory - P11'!H23&" | ")&IF('Inventory - P11'!H24="","",'Inventory - P11'!H24&" | ")&IF('Inventory - P11'!H25="","",'Inventory - P11'!H25&" | ")&IF('Inventory - P11'!H26="","",'Inventory - P11'!H26&" | ")&IF('Inventory - P11'!H27="","",'Inventory - P11'!H27&" | ")="","",LEFT(IF('Inventory - P11'!H16="","",'Inventory - P11'!H16&" | ")&IF('Inventory - P11'!H17="","",'Inventory - P11'!H17&" | ")&IF('Inventory - P11'!H18="","",'Inventory - P11'!H18&" | ")&IF('Inventory - P11'!H19="","",'Inventory - P11'!H19&" | ")&IF('Inventory - P11'!H20="","",'Inventory - P11'!H20&" | ")&IF('Inventory - P11'!H21="","",'Inventory - P11'!H21&" | ")&IF('Inventory - P11'!H22="","",'Inventory - P11'!H22&" | ")&IF('Inventory - P11'!H23="","",'Inventory - P11'!H23&" | ")&IF('Inventory - P11'!H24="","",'Inventory - P11'!H24&" | ")&IF('Inventory - P11'!H25="","",'Inventory - P11'!H25&" | ")&IF('Inventory - P11'!H26="","",'Inventory - P11'!H26&" | ")&IF('Inventory - P11'!H27="","",'Inventory - P11'!H27&" | "),LEN(IF('Inventory - P11'!H16="","",'Inventory - P11'!H16&" | ")&IF('Inventory - P11'!H17="","",'Inventory - P11'!H17&" | ")&IF('Inventory - P11'!H18="","",'Inventory - P11'!H18&" | ")&IF('Inventory - P11'!H19="","",'Inventory - P11'!H19&" | ")&IF('Inventory - P11'!H20="","",'Inventory - P11'!H20&" | ")&IF('Inventory - P11'!H21="","",'Inventory - P11'!H21&" | ")&IF('Inventory - P11'!H22="","",'Inventory - P11'!H22&" | ")&IF('Inventory - P11'!H23="","",'Inventory - P11'!H23&" | ")&IF('Inventory - P11'!H24="","",'Inventory - P11'!H24&" | ")&IF('Inventory - P11'!H25="","",'Inventory - P11'!H25&" | ")&IF('Inventory - P11'!H26="","",'Inventory - P11'!H26&" | ")&IF('Inventory - P11'!H27="","",'Inventory - P11'!H27&" | "))-3)) | N15: =IF('Client Needs Tracker'!E15="","",'Client Needs Tracker'!E15) | O15: =IF('Client Needs Tracker'!C15="","",'Client Needs Tracker'!C15) -> 46237
A16: ='Client Needs Tracker'!A16 -> 25585 | B16: =IF('Client Needs Tracker'!B16="","",UPPER(LEFT(TRIM('Client Needs Tracker'!B16),1))&"."&UPPER(MID('Client Needs Tracker'!B16,FIND("@",SUBSTITUTE('Client Needs Tracker'!B16," ","@",LEN('Client Needs Tracker'!B16)-LEN(SUBSTITUTE('Client Needs Tracker'!B16," ",""))))+1,1))&".") -> L.K. | C16: =IF('Client Needs Tracker'!S16="","",'Client Needs Tracker'!S16) -> F - 2B | D16: =IF('Client Needs Tracker'!G16="","",'Client Needs Tracker'!G16) | E16: =IF('Client Needs Tracker'!F16="","",'Client Needs Tracker'!F16) | F16: Scheduled | K16: Submitted/Pending | M16: =IF(IF('Inventory - P12'!H16="","",'Inventory - P12'!H16&" | ")&IF('Inventory - P12'!H17="","",'Inventory - P12'!H17&" | ")&IF('Inventory - P12'!H18="","",'Inventory - P12'!H18&" | ")&IF('Inventory - P12'!H19="","",'Inventory - P12'!H19&" | ")&IF('Inventory - P12'!H20="","",'Inventory - P12'!H20&" | ")&IF('Inventory - P12'!H21="","",'Inventory - P12'!H21&" | ")&IF('Inventory - P12'!H22="","",'Inventory - P12'!H22&" | ")&IF('Inventory - P12'!H23="","",'Inventory - P12'!H23&" | ")&IF('Inventory - P12'!H24="","",'Inventory - P12'!H24&" | ")&IF('Inventory - P12'!H25="","",'Inventory - P12'!H25&" | ")&IF('Inventory - P12'!H26="","",'Inventory - P12'!H26&" | ")&IF('Inventory - P12'!H27="","",'Inventory - P12'!H27&" | ")="","",LEFT(IF('Inventory - P12'!H16="","",'Inventory - P12'!H16&" | ")&IF('Inventory - P12'!H17="","",'Inventory - P12'!H17&" | ")&IF('Inventory - P12'!H18="","",'Inventory - P12'!H18&" | ")&IF('Inventory - P12'!H19="","",'Inventory - P12'!H19&" | ")&IF('Inventory - P12'!H20="","",'Inventory - P12'!H20&" | ")&IF('Inventory - P12'!H21="","",'Inventory - P12'!H21&" | ")&IF('Inventory - P12'!H22="","",'Inventory - P12'!H22&" | ")&IF('Inventory - P12'!H23="","",'Inventory - P12'!H23&" | ")&IF('Inventory - P12'!H24="","",'Inventory - P12'!H24&" | ")&IF('Inventory - P12'!H25="","",'Inventory - P12'!H25&" | ")&IF('Inventory - P12'!H26="","",'Inventory - P12'!H26&" | ")&IF('Inventory - P12'!H27="","",'Inventory - P12'!H27&" | "),LEN(IF('Inventory - P12'!H16="","",'Inventory - P12'!H16&" | ")&IF('Inventory - P12'!H17="","",'Inventory - P12'!H17&" | ")&IF('Inventory - P12'!H18="","",'Inventory - P12'!H18&" | ")&IF('Inventory - P12'!H19="","",'Inventory - P12'!H19&" | ")&IF('Inventory - P12'!H20="","",'Inventory - P12'!H20&" | ")&IF('Inventory - P12'!H21="","",'Inventory - P12'!H21&" | ")&IF('Inventory - P12'!H22="","",'Inventory - P12'!H22&" | ")&IF('Inventory - P12'!H23="","",'Inventory - P12'!H23&" | ")&IF('Inventory - P12'!H24="","",'Inventory - P12'!H24&" | ")&IF('Inventory - P12'!H25="","",'Inventory - P12'!H25&" | ")&IF('Inventory - P12'!H26="","",'Inventory - P12'!H26&" | ")&IF('Inventory - P12'!H27="","",'Inventory - P12'!H27&" | "))-3)) | N16: =IF('Client Needs Tracker'!E16="","",'Client Needs Tracker'!E16) | O16: =IF('Client Needs Tracker'!C16="","",'Client Needs Tracker'!C16) -> 46239
A17: ='Client Needs Tracker'!A17 -> 588588 | B17: =IF('Client Needs Tracker'!B17="","",UPPER(LEFT(TRIM('Client Needs Tracker'!B17),1))&"."&UPPER(MID('Client Needs Tracker'!B17,FIND("@",SUBSTITUTE('Client Needs Tracker'!B17," ","@",LEN('Client Needs Tracker'!B17)-LEN(SUBSTITUTE('Client Needs Tracker'!B17," ",""))))+1,1))&".") -> J.S. | C17: =IF('Client Needs Tracker'!S17="","",'Client Needs Tracker'!S17) -> F - 3A | D17: =IF('Client Needs Tracker'!G17="","",'Client Needs Tracker'!G17) | E17: =IF('Client Needs Tracker'!F17="","",'Client Needs Tracker'!F17) | F17: Scheduled | K17: Submitted/Pending | M17: =IF(IF('Inventory - P13'!H16="","",'Inventory - P13'!H16&" | ")&IF('Inventory - P13'!H17="","",'Inventory - P13'!H17&" | ")&IF('Inventory - P13'!H18="","",'Inventory - P13'!H18&" | ")&IF('Inventory - P13'!H19="","",'Inventory - P13'!H19&" | ")&IF('Inventory - P13'!H20="","",'Inventory - P13'!H20&" | ")&IF('Inventory - P13'!H21="","",'Inventory - P13'!H21&" | ")&IF('Inventory - P13'!H22="","",'Inventory - P13'!H22&" | ")&IF('Inventory - P13'!H23="","",'Inventory - P13'!H23&" | ")&IF('Inventory - P13'!H24="","",'Inventory - P13'!H24&" | ")&IF('Inventory - P13'!H25="","",'Inventory - P13'!H25&" | ")&IF('Inventory - P13'!H26="","",'Inventory - P13'!H26&" | ")&IF('Inventory - P13'!H27="","",'Inventory - P13'!H27&" | ")="","",LEFT(IF('Inventory - P13'!H16="","",'Inventory - P13'!H16&" | ")&IF('Inventory - P13'!H17="","",'Inventory - P13'!H17&" | ")&IF('Inventory - P13'!H18="","",'Inventory - P13'!H18&" | ")&IF('Inventory - P13'!H19="","",'Inventory - P13'!H19&" | ")&IF('Inventory - P13'!H20="","",'Inventory - P13'!H20&" | ")&IF('Inventory - P13'!H21="","",'Inventory - P13'!H21&" | ")&IF('Inventory - P13'!H22="","",'Inventory - P13'!H22&" | ")&IF('Inventory - P13'!H23="","",'Inventory - P13'!H23&" | ")&IF('Inventory - P13'!H24="","",'Inventory - P13'!H24&" | ")&IF('Inventory - P13'!H25="","",'Inventory - P13'!H25&" | ")&IF('Inventory - P13'!H26="","",'Inventory - P13'!H26&" | ")&IF('Inventory - P13'!H27="","",'Inventory - P13'!H27&" | "),LEN(IF('Inventory - P13'!H16="","",'Inventory - P13'!H16&" | ")&IF('Inventory - P13'!H17="","",'Inventory - P13'!H17&" | ")&IF('Inventory - P13'!H18="","",'Inventory - P13'!H18&" | ")&IF('Inventory - P13'!H19="","",'Inventory - P13'!H19&" | ")&IF('Inventory - P13'!H20="","",'Inventory - P13'!H20&" | ")&IF('Inventory - P13'!H21="","",'Inventory - P13'!H21&" | ")&IF('Inventory - P13'!H22="","",'Inventory - P13'!H22&" | ")&IF('Inventory - P13'!H23="","",'Inventory - P13'!H23&" | ")&IF('Inventory - P13'!H24="","",'Inventory - P13'!H24&" | ")&IF('Inventory - P13'!H25="","",'Inventory - P13'!H25&" | ")&IF('Inventory - P13'!H26="","",'Inventory - P13'!H26&" | ")&IF('Inventory - P13'!H27="","",'Inventory - P13'!H27&" | "))-3)) | N17: =IF('Client Needs Tracker'!E17="","",'Client Needs Tracker'!E17) | O17: =IF('Client Needs Tracker'!C17="","",'Client Needs Tracker'!C17) -> 46238
